Workbook

Sheet Pull out test IPE 160
T5: Ensayo 3 IPE 160
C6: Ensayo 1 IPE 160 | K6: Ensayo 2 IPE 160 | T6: Prueba de tensión vertical
C7: Prueba de tensión vertical | K7: Prueba de tensión vertical | T7: Desplazamiento [mm] | U7: Fuerza [kg]
C8: Desplazamiento [mm] | D8: Fuerza [kg] | K8: Desplazamiento [mm] | L8: Fuerza [kg] | T8: 0 | U8: 0
C9: 0 | D9: 0 | K9: 0 | L9: 0 | T9: 0.2 | U9: 354
C10: 0.25 | D10: 326 | K10: 0.09 | L10: 402 | T10: 0.9 | U10: 580
C11: 2.4 | D11: 618 | K11: 0.23 | L11: 618 | T11: 1.6 | U11: 761
C12: 4.74 | D12: 861 | K12: 0.71 | L12: 817 | T12: 7.73 | U12: 1140
C13: 12.09 | D13: 1032 | K13: 1.11 | L13: 1046 | T13: 18.87 | U13: 1374
C14: 25.59 | D14: 1164 | K14: 2.16 | L14: 1302 | T14: 25.49 | U14: 1402
C15: Profundidad de hinca [m] | D15: 2.5 | K15: 3.51 | L15: 1450 | T15: Profundidad de hinca [m] | U15: 2.5
K16: 6.53 | L16: 1652
K17: 14.79 | L17: 1862
K18: 25.65 | L18: 1932
K19: Profundidad de hinca [m] | L19: 2.5
C23: Ensayo 1 IPE 160 | K23: Ensayo 2 IPE 160 | T23: Ensayo 2 IPE 160
C24: Prueba de compresión vertical | K24: Prueba de compresión vertical | T24: Prueba de compresión vertical
C25: Desplazamiento [mm] | D25: Fuerza [kg] | K25: Desplazamiento [mm] | L25: Fuerza [kg] | T25: Desplazamiento [mm] | U25: Fuerza [kg]
C26: 0 | D26: 0 | K26: 0 | L26: 0 | T26: 0 | U26: 0
C27: 12.18 | D27: 342 | K27: 1.07 | L27: 349 | T27: 10.46 | U27: 332
C28: 25.8 | D28: 425 | K28: 3.16 | L28: 520 | T28: 25.8 | U28: 420
C29: Profundidad de hinca [m] | D29: 2.5 | K29: 6.78 | L29: 781 | T29: Profundidad de hinca [m] | U29: 2.5
K30: 25.5 | L30: 984
K31: Profundidad de hinca [m] | L31: 2.5
C38: Ensayo 1 IPE 160 | K38: Ensayo 2 IPE 160 | T38: Ensayo 2 IPE 160
C39: Prueba de carga lateral | K39: Prueba de carga lateral | T39: Prueba de carga lateral
C40: Desplazamiento [mm] | D40: Fuerza [kg] | K40: Desplazamiento [mm] | L40: Fuerza [kg] | T40: Desplazamiento [mm] | U40: Fuerza [kg]
C41: 0 | D41: 0 | K41: 0 | L41: 0 | T41: 0 | U41: 0
C42: 4.44 | D42: 350 | K42: 2.2 | L42: 310 | T42: 3.08 | U42: 320
C43: 6.64 | D43: 524 | K43: 3.12 | L43: 550 | T43: 4.28 | U43: 530
C44: 10.11 | D44: 718 | K44: 4.43 | L44: 728 | T44: 6.64 | U44: 742
C45: 17.26 | D45: 1030 | K45: 6.89 | L45: 1040 | T45: 10.4 | U45: 1036
C46: 24.6 | D46: 1240 | K46: 9.58 | L46: 1268 | T46: 14.12 | U46: 1280
C47: 25.57 | D47: 1320 | K47: 11.54 | L47: 1462 | T47: 16.9 | U47: 1465
C48: Profundidad de hinca [m] | D48: 2.5 | K48: 13.9 | L48: 1654 | T48: 20.5 | U48: 1634
K49: 16.7 | L49: 1869 | T49: 24.6 | U49: 1840
K50: 20.7 | L50: 2072 | T50: 25.3 | U50: 1936
K51: Profundidad de hinca [m] | L51: 2.5 | T51: Profundidad de hinca [m] | U51: 2.5

Sheet Interpolación para W8X10
C2: Item | D2: H | E2: B
C3: Dimensiones IPE 160 | D3: 160 | E3: 82 | F3: 160 | G3: Nota el ensayo fue realizado por el lado fuerte
C4: Dimensiones W8X10 (Ala aumentada) | D4: 198 | E4: =100+70 -> 170 | F4: 198
C5: Correlación dimensional IPE 160 a W8X10 (Ala extendida) | D5: =D4/D3 -> 1.2375 | E5: =E4/E3 -> 2.0731707 | G5: Cambiar a 8X10
AL8: CARGAS DE SERVICIO POSTE W8X10
T9: Correlación prueba vertical 3 para W8X10 | AL9: FX (kN) | AM9: FY (kN) | AN9: FY (kN) | AO9: Carga maxima lateral (kg) | AP9: F.S. Carga lateral | AQ9: FZ (kN) | AR9: Fz (kg) | AS9: Carga maxima a tensión (kg) | AT9: F.S Tensión | AU9: Carga maxima a compresión (kg) | AV9: F.S Compresión | AW9: MX (kNm) | AX9: Carga horizontal equivalente (kg) | AY9: MY (kNm) | AZ9: MZ (kNm) | BA9: Case name
C10: Correlación prueba vertical 1 para W8X10 | K10: Correlación prueba vertical 2 para W8X10 | T10: Prueba de tensión vertical | AK10: Poste General | AL10: 0 | AM10: -0.52 | AN10: =AM10*101.97 -> -53.0244 | AO10: 2736.59 | AP10: =ABS(AO10/AN10) -> 51.610014 | AQ10: 3.5 | AR10: =AQ10*101.97 -> 356.895 | AS10: -2413 | AT10: =IF(AS10/AR10>=0,AS10/AR10, "Compresión no aplica") -> Compresión no aplica | AU10: 881.1 | AV10: =IF(AU10/AR10>=0,AU10/AR10, "Tensión no aplica") -> 2.4687933 | AW10: 0.78 | AX10: =AM10*101.97 -> -53.0244 | AY10: -0.35 | AZ10: 0 | BA10: D+W15(+)
C11: Prueba de tensión vertical | K11: Prueba de tensión vertical | T11: Desplazamiento [mm] | U11: Fuerza [kg] | AK11: Poste General | AL11: 0 | AM11: 0.46 | AN11: =AM11*101.97 -> 46.9062 | AO11: 2736.59 | AP11: =ABS(AO11/AN11) -> 58.341754 | AQ11: -0.24 | AR11: =AQ11*101.97 -> -24.4728 | AS11: -2413 | AT11: =IF(AS11/AR11>=0,AS11/AR11, "Compresión no aplica") -> 98.599261 | AU11: 881.1 | AV11: =IF(AU11/AR11>=0,AU11/AR11, "Tensión no aplica") -> Tensión no aplica | AW11: -0.69 | AX11: =AM11*101.97 -> 46.9062 | AY11: 0.04 | AZ11: 0 | BA11: D+W15(-)
C12: Desplazamiento [mm] | D12: Fuerza [kg] | K12: Desplazamiento [mm] | L12: Fuerza [kg] | T12: ='Pull out test IPE 160'!T8 -> 0 | U12: ='Pull out test IPE 160'!U8*'Interpolación para W8X10'!$E$5 -> 0 | AK12: Poste General | AL12: 0 | AM12: -2.35 | AN12: =AM12*101.97 -> -239.6295 | AO12: 2736.59 | AP12: =ABS(AO12/AN12) -> 11.420088 | AQ12: 2.88 | AR12: =AQ12*101.97 -> 293.6736 | AS12: -2413 | AT12: =IF(AS12/AR12>=0,AS12/AR12, "Compresión no aplica") -> Compresión no aplica | AU12: 881.1 | AV12: =IF(AU12/AR12>=0,AU12/AR12, "Tensión no aplica") -> 3.0002697 | AW12: 3.51 | AX12: =AM12*101.97 -> -239.6295 | AY12: -0.29 | AZ12: 0 | BA12: D+W60(+)
C13: ='Pull out test IPE 160'!C9 -> 0 | D13: ='Pull out test IPE 160'!D9*'Interpolación para W8X10'!$E$5 -> 0 | K13: ='Pull out test IPE 160'!K9 -> 0 | L13: ='Pull out test IPE 160'!L9*'Interpolación para W8X10'!$E$5 -> 0 | T13: ='Pull out test IPE 160'!T9 -> 0.2 | U13: ='Pull out test IPE 160'!U9*'Interpolación para W8X10'!$E$5 -> 733.90244 | AK13: Poste General | AL13: 0 | AM13: 2.02 | AN13: =AM13*101.97 -> 205.9794 | AO13: 2736.59 | AP13: =ABS(AO13/AN13) -> 13.285746 | AQ13: 0.32 | AR13: =AQ13*101.97 -> 32.6304 | AS13: -2413 | AT13: =IF(AS13/AR13>=0,AS13/AR13, "Compresión no aplica") -> Compresión no aplica | AU13: 881.1 | AV13: =IF(AU13/AR13>=0,AU13/AR13, "Tensión no aplica") -> 27.002427 | AW13: -3.02 | AX13: =AM13*101.97 -> 205.9794 | AY13: -0.02 | AZ13: 0 | BA13: D+W60(-)
C14: ='Pull out test IPE 160'!C10 -> 0.25 | D14: ='Pull out test IPE 160'!D10*'Interpolación para W8X10'!$E$5 -> 675.85366 | K14: ='Pull out test IPE 160'!K10 -> 0.09 | L14: ='Pull out test IPE 160'!L10*'Interpolación para W8X10'!$E$5 -> 833.41463 | T14: ='Pull out test IPE 160'!T10 -> 0.9 | U14: ='Pull out test IPE 160'!U10*'Interpolación para W8X10'!$E$5 -> 1202.439 | AK14: Poste General | AL14: 0 | AM14: -0.52 | AN14: =AM14*101.97 -> -53.0244 | AO14: 2736.59 | AP14: =ABS(AO14/AN14) -> 51.610014 | AQ14: 2.9 | AR14: =AQ14*101.97 -> 295.713 | AS14: -2413 | AT14: =IF(AS14/AR14>=0,AS14/AR14, "Compresión no aplica") -> Compresión no aplica | AU14: 881.1 | AV14: =IF(AU14/AR14>=0,AU14/AR14, "Tensión no aplica") -> 2.9795782 | AW14: 0.78 | AX14: =AM14*101.97 -> -53.0244 | AY14: -0.3 | AZ14: 0 | BA14: 0.6D+W15(+)
C15: ='Pull out test IPE 160'!C11 -> 2.4 | D15: ='Pull out test IPE 160'!D11*'Interpolación para W8X10'!$E$5 -> 1281.2195 | K15: ='Pull out test IPE 160'!K11 -> 0.23 | L15: ='Pull out test IPE 160'!L11*'Interpolación para W8X10'!$E$5 -> 1281.2195 | T15: ='Pull out test IPE 160'!T11 -> 1.6 | U15: ='Pull out test IPE 160'!U11*'Interpolación para W8X10'!$E$5 -> 1577.6829 | AK15: Poste General | AL15: 0 | AM15: 0.46 | AN15: =AM15*101.97 -> 46.9062 | AO15: 2736.59 | AP15: =ABS(AO15/AN15) -> 58.341754 | AQ15: -0.84 | AR15: =AQ15*101.97 -> -85.6548 | AS15: -2413 | AT15: =IF(AS15/AR15>=0,AS15/AR15, "Compresión no aplica") -> 28.171217 | AU15: 881.1 | AV15: =IF(AU15/AR15>=0,AU15/AR15, "Tensión no aplica") -> Tensión no aplica | AW15: -0.69 | AX15: =AM15*101.97 -> 46.9062 | AY15: 0.1 | AZ15: 0 | BA15: 0.6D+W15(-)
C16: ='Pull out test IPE 160'!C12 -> 4.74 | D16: ='Pull out test IPE 160'!D12*'Interpolación para W8X10'!$E$5 -> 1785 | K16: ='Pull out test IPE 160'!K12 -> 0.71 | L16: ='Pull out test IPE 160'!L12*'Interpolación para W8X10'!$E$5 -> 1693.7805 | T16: ='Pull out test IPE 160'!T12 -> 7.73 | U16: ='Pull out test IPE 160'!U12*'Interpolación para W8X10'!$E$5 -> 2363.4146 | AK16: Poste General | AL16: 0 | AM16: -2.35 | AN16: =AM16*101.97 -> -239.6295 | AO16: 2736.59 | AP16: =ABS(AO16/AN16) -> 11.420088 | AQ16: 2.27 | AR16: =AQ16*101.97 -> 231.4719 | AS16: -2413 | AT16: =IF(AS16/AR16>=0,AS16/AR16, "Compresión no aplica") -> Compresión no aplica | AU16: 881.1 | AV16: =IF(AU16/AR16>=0,AU16/AR16, "Tensión no aplica") -> 3.8065096 | AW16: 3.51 | AX16: =AM16*101.97 -> -239.6295 | AY16: -0.23 | AZ16: 0 | BA16: 0.6D+W60(+)
C17: ='Pull out test IPE 160'!C13 -> 12.09 | D17: ='Pull out test IPE 160'!D13*'Interpolación para W8X10'!$E$5 -> 2139.5122 | K17: ='Pull out test IPE 160'!K13 -> 1.11 | L17: ='Pull out test IPE 160'!L13*'Interpolación para W8X10'!$E$5 -> 2168.5366 | T17: ='Pull out test IPE 160'!T13 -> 18.87 | U17: ='Pull out test IPE 160'!U13*'Interpolación para W8X10'!$E$5 -> 2848.5366 | AK17: Poste General | AL17: 0 | AM17: 2.02 | AN17: =AM17*101.97 -> 205.9794 | AO17: 2736.59 | AP17: =ABS(AO17/AN17) -> 13.285746 | AQ17: -0.28 | AR17: =AQ17*101.97 -> -28.5516 | AS17: -2413 | AT17: =IF(AS17/AR17>=0,AS17/AR17, "Compresión no aplica") -> 84.513652 | AU17: 881.1 | AV17: =IF(AU17/AR17>=0,AU17/AR17, "Tensión no aplica") -> Tensión no aplica | AW17: -3.02 | AX17: =AM17*101.97 -> 205.9794 | AY17: 0.04 | AZ17: 0 | BA17: 0.6D+W60(-)
C18: ='Pull out test IPE 160'!C14 -> 25.59 | D18: ='Pull out test IPE 160'!D14*'Interpolación para W8X10'!$E$5 -> 2413.1707 | K18: ='Pull out test IPE 160'!K14 -> 2.16 | L18: ='Pull out test IPE 160'!L14*'Interpolación para W8X10'!$E$5 -> 2699.2683 | T18: ='Pull out test IPE 160'!T14 -> 25.49 | U18: ='Pull out test IPE 160'!U14*'Interpolación para W8X10'!$E$5 -> 2906.5854 | AK18: Poste General | AL18: 0 | AM18: 0.0001 | AN18: =AM18*101.97 -> 0.010197 | AO18: 2736.59 | AP18: =ABS(AO18/AN18) -> 268372.07 | AQ18: 1.51 | AR18: =AQ18*101.97 -> 153.9747 | AS18: -2413 | AT18: =IF(AS18/AR18>=0,AS18/AR18, "Compresión no aplica") -> Compresión no aplica | AU18: 881.1 | AV18: =IF(AU18/AR18>=0,AU18/AR18, "Tensión no aplica") -> 5.7223687 | AW18: 0 | AX18: =AM18*101.97 -> 0.010197 | AY18: -0.14 | AZ18: 0 | BA18: D
C19: Profundidad de hinca [m] | D19: 2.5 | K19: ='Pull out test IPE 160'!K15 -> 3.51 | L19: ='Pull out test IPE 160'!L15*'Interpolación para W8X10'!$E$5 -> 3006.0976 | T19: Profundidad de hinca [m] | U19: 2.5 | AK19: Poste General | AL19: 0 | AM19: -0.23 | AN19: =AM19*101.97 -> -23.4531 | AO19: 2736.59 | AP19: =ABS(AO19/AN19) -> 116.68351 | AQ19: 1.67 | AR19: =AQ19*101.97 -> 170.2899 | AS19: -2413 | AT19: =IF(AS19/AR19>=0,AS19/AR19, "Compresión no aplica") -> Compresión no aplica | AU19: 881.1 | AV19: =IF(AU19/AR19>=0,AU19/AR19, "Tensión no aplica") -> 5.1741178 | AW19: 0.35 | AX19: =AM19*101.97 -> -23.4531 | AY19: -0.16 | AZ19: 0 | BA19: D+0.7E
K20: ='Pull out test IPE 160'!K16 -> 6.53 | L20: ='Pull out test IPE 160'!L16*'Interpolación para W8X10'!$E$5 -> 3424.878 | AK20: Poste General | AL20: 0 | AM20: -0.23 | AN20: =AM20*101.97 -> -23.4531 | AO20: 2736.59 | AP20: =ABS(AO20/AN20) -> 116.68351 | AQ20: 1.06 | AR20: =AQ20*101.97 -> 108.0882 | AS20: -2413 | AT20: =IF(AS20/AR20>=0,AS20/AR20, "Compresión no aplica") -> Compresión no aplica | AU20: 881.1 | AV20: =IF(AU20/AR20>=0,AU20/AR20, "Tensión no aplica") -> 8.1516761 | AW20: 0.35 | AX20: =AM20*101.97 -> -23.4531 | AY20: -0.1 | AZ20: 0 | BA20: 0.6D+0.7E
K21: ='Pull out test IPE 160'!K17 -> 14.79 | L21: ='Pull out test IPE 160'!L17*'Interpolación para W8X10'!$E$5 -> 3860.2439 | AK21: Poste General | AL21: 0 | AM21: -0.39 | AN21: =AM21*101.97 -> -39.7683 | AO21: 2736.59 | AP21: =ABS(AO21/AN21) -> 68.813351 | AQ21: 3 | AR21: =AQ21*101.97 -> 305.91 | AS21: -2413 | AT21: =IF(AS21/AR21>=0,AS21/AR21, "Compresión no aplica") -> Compresión no aplica | AU21: 881.1 | AV21: =IF(AU21/AR21>=0,AU21/AR21, "Tensión no aplica") -> 2.8802589 | AW21: 0.59 | AX21: =AM21*101.97 -> -39.7683 | AY21: -0.3 | AZ21: 0 | BA21: D+0.75W15(+)
K22: ='Pull out test IPE 160'!K18 -> 25.65 | L22: ='Pull out test IPE 160'!L18*'Interpolación para W8X10'!$E$5 -> 4005.3659 | AK22: Poste General | AL22: 0 | AM22: 0.35 | AN22: =AM22*101.97 -> 35.6895 | AO22: 2736.59 | AP22: =ABS(AO22/AN22) -> 76.677734 | AQ22: 0.2 | AR22: =AQ22*101.97 -> 20.394 | AS22: -2413 | AT22: =IF(AS22/AR22>=0,AS22/AR22, "Compresión no aplica") -> Compresión no aplica | AU22: 881.1 | AV22: =IF(AU22/AR22>=0,AU22/AR22, "Tensión no aplica") -> 43.203883 | AW22: -0.52 | AX22: =AM22*101.97 -> 35.6895 | AY22: 0 | AZ22: 0 | BA22: D+0.75 W15(-)
K23: Profundidad de hinca [m] | L23: 2.5 | AK23: Poste General | AL23: 0 | AM23: -1.76 | AN23: =AM23*101.97 -> -179.4672 | AO23: 2736.59 | AP23: =ABS(AO23/AN23) -> 15.248413 | AQ23: 2.54 | AR23: =AQ23*101.97 -> 259.0038 | AS23: -2413 | AT23: =IF(AS23/AR23>=0,AS23/AR23, "Compresión no aplica") -> Compresión no aplica | AU23: 881.1 | AV23: =IF(AU23/AR23>=0,AU23/AR23, "Tensión no aplica") -> 3.4018806 | AW23: 2.63 | AX23: =AM23*101.97 -> -179.4672 | AY23: -0.25 | AZ23: 0 | BA23: D+0.75W60(+)
AK24: Poste General | AL24: 0 | AM24: 1.51 | AN24: =AM24*101.97 -> 153.9747 | AO24: 2736.59 | AP24: =ABS(AO24/AN24) -> 17.772985 | AQ24: 0.62 | AR24: =AQ24*101.97 -> 63.2214 | AS24: -2413 | AT24: =IF(AS24/AR24>=0,AS24/AR24, "Compresión no aplica") -> Compresión no aplica | AU24: 881.1 | AV24: =IF(AU24/AR24>=0,AU24/AR24, "Tensión no aplica") -> 13.936737 | AW24: -2.27 | AX24: =AM24*101.97 -> 153.9747 | AY24: -0.05 | AZ24: 0 | BA24: D+0.75W60(-)
AK25: Poste General | AL25: 0 | AM25: -0.88 | AN25: =AM25*101.97 -> -89.7336 | AO25: 2736.59 | AP25: =ABS(AO25/AN25) -> 30.496826 | AQ25: 5.62 | AR25: =AQ25*101.97 -> 573.0714 | AS25: -2413 | AT25: =IF(AS25/AR25>=0,AS25/AR25, "Compresión no aplica") -> Compresión no aplica | AU25: 881.1 | AV25: =IF(AU25/AR25>=0,AU25/AR25, "Tensión no aplica") -> 1.5375048 | AW25: 1.32 | AX25: =AM25*101.97 -> -89.7336 | AY25: 0.04 | AZ25: 0 | BA25: D+W15(+)
AK26: Poste General | AL26: 0 | AM26: 0.77 | AN26: =AM26*101.97 -> 78.5169 | AO26: 2736.59 | AP26: =ABS(AO26/AN26) -> 34.853516 | AQ26: -0.48 | AR26: =AQ26*101.97 -> -48.9456 | AS26: -2413 | AT26: =IF(AS26/AR26>=0,AS26/AR26, "Compresión no aplica") -> 49.299631 | AU26: 881.1 | AV26: =IF(AU26/AR26>=0,AU26/AR26, "Tensión no aplica") -> Tensión no aplica | AW26: -1.16 | AX26: =AM26*101.97 -> 78.5169 | AY26: -0.01 | AZ26: 0 | BA26: D+W15(-)
C27: Correlación prueba vertical 1 para W8X10 | K27: Correlación prueba vertical 2 para W8X10 | T27: Correlación prueba vertical 3 para W8X10 | AK27: Poste General | AL27: 0 | AM27: -3.95 | AN27: =AM27*101.97 -> -402.7815 | AO27: 2736.59 | AP27: =ABS(AO27/AN27) -> 6.7942296 | AQ27: 4.6 | AR27: =AQ27*101.97 -> 469.062 | AS27: -2413 | AT27: =IF(AS27/AR27>=0,AS27/AR27, "Compresión no aplica") -> Compresión no aplica | AU27: 881.1 | AV27: =IF(AU27/AR27>=0,AU27/AR27, "Tensión no aplica") -> 1.8784297 | AW27: 5.91 | AX27: =AM27*101.97 -> -402.7815 | AY27: 0.03 | AZ27: 0 | BA27: D+W60(+)
C28: Prueba de compresión vertical | K28: Prueba de compresión vertical | T28: Prueba de compresión vertical | AK28: Poste General | AL28: 0 | AM28: 3.4 | AN28: =AM28*101.97 -> 346.698 | AO28: 2736.59 | AP28: =ABS(AO28/AN28) -> 7.8932962 | AQ28: 0.43 | AR28: =AQ28*101.97 -> 43.8471 | AS28: -2413 | AT28: =IF(AS28/AR28>=0,AS28/AR28, "Compresión no aplica") -> Compresión no aplica | AU28: 881.1 | AV28: =IF(AU28/AR28>=0,AU28/AR28, "Tensión no aplica") -> 20.09483 | AW28: -5.08 | AX28: =AM28*101.97 -> 346.698 | AY28: 0 | AZ28: 0 | BA28: D+W60(-)
C29: Desplazamiento [mm] | D29: Fuerza [kg] | K29: Desplazamiento [mm] | L29: Fuerza [kg] | T29: Desplazamiento [mm] | U29: Fuerza [kg] | AK29: Poste General | AL29: 0 | AM29: -0.88 | AN29: =AM29*101.97 -> -89.7336 | AO29: 2736.59 | AP29: =ABS(AO29/AN29) -> 30.496826 | AQ29: 4.67 | AR29: =AQ29*101.97 -> 476.1999 | AS29: -2413 | AT29: =IF(AS29/AR29>=0,AS29/AR29, "Compresión no aplica") -> Compresión no aplica | AU29: 881.1 | AV29: =IF(AU29/AR29>=0,AU29/AR29, "Tensión no aplica") -> 1.8502734 | AW29: 1.32 | AX29: =AM29*101.97 -> -89.7336 | AY29: 0.03 | AZ29: 0 | BA29: 0.6D+W15(+)
C30: ='Pull out test IPE 160'!C26 -> 0 | D30: ='Pull out test IPE 160'!D26*'Interpolación para W8X10'!$E$5 -> 0 | K30: ='Pull out test IPE 160'!K26 -> 0 | L30: ='Pull out test IPE 160'!L9*'Interpolación para W8X10'!$E$5 -> 0 | T30: ='Pull out test IPE 160'!T26 -> 0 | U30: ='Pull out test IPE 160'!U26*'Interpolación para W8X10'!$E$5 -> 0 | AK30: Poste General | AL30: 0 | AM30: 0.77 | AN30: =AM30*101.97 -> 78.5169 | AO30: 2736.59 | AP30: =ABS(AO30/AN30) -> 34.853516 | AQ30: -1.43 | AR30: =AQ30*101.97 -> -145.8171 | AS30: -2413 | AT30: =IF(AS30/AR30>=0,AS30/AR30, "Compresión no aplica") -> 16.548128 | AU30: 881.1 | AV30: =IF(AU30/AR30>=0,AU30/AR30, "Tensión no aplica") -> Tensión no aplica | AW30: -1.16 | AX30: =AM30*101.97 -> 78.5169 | AY30: -0.01 | AZ30: 0 | BA30: 0.6D+W15(-)
C31: ='Pull out test IPE 160'!C27 -> 12.18 | D31: ='Pull out test IPE 160'!D27*'Interpolación para W8X10'!$E$5 -> 709.02439 | K31: ='Pull out test IPE 160'!K27 -> 1.07 | L31: ='Pull out test IPE 160'!L10*'Interpolación para W8X10'!$E$5 -> 833.41463 | T31: ='Pull out test IPE 160'!T27 -> 10.46 | U31: ='Pull out test IPE 160'!U27*'Interpolación para W8X10'!$E$5 -> 688.29268 | AK31: Poste General | AL31: 0 | AM31: -3.95 | AN31: =AM31*101.97 -> -402.7815 | AO31: 2736.59 | AP31: =ABS(AO31/AN31) -> 6.7942296 | AQ31: 3.65 | AR31: =AQ31*101.97 -> 372.1905 | AS31: -2413 | AT31: =IF(AS31/AR31>=0,AS31/AR31, "Compresión no aplica") -> Compresión no aplica | AU31: 881.1 | AV31: =IF(AU31/AR31>=0,AU31/AR31, "Tensión no aplica") -> 2.3673361 | AW31: 5.91 | AX31: =AM31*101.97 -> -402.7815 | AY31: 0.03 | AZ31: 0 | BA31: 0.6D+W60(+)
C32: ='Pull out test IPE 160'!C28 -> 25.8 | D32: ='Pull out test IPE 160'!D28*'Interpolación para W8X10'!$E$5 -> 881.09756 | K32: ='Pull out test IPE 160'!K28 -> 3.16 | L32: ='Pull out test IPE 160'!L11*'Interpolación para W8X10'!$E$5 -> 1281.2195 | T32: ='Pull out test IPE 160'!T28 -> 25.8 | U32: ='Pull out test IPE 160'!U28*'Interpolación para W8X10'!$E$5 -> 870.73171 | AK32: Poste General | AL32: 0 | AM32: 3.4 | AN32: =AM32*101.97 -> 346.698 | AO32: 2736.59 | AP32: =ABS(AO32/AN32) -> 7.8932962 | AQ32: -0.52 | AR32: =AQ32*101.97 -> -53.0244 | AS32: -2413 | AT32: =IF(AS32/AR32>=0,AS32/AR32, "Compresión no aplica") -> 45.507351 | AU32: 881.1 | AV32: =IF(AU32/AR32>=0,AU32/AR32, "Tensión no aplica") -> Tensión no aplica | AW32: -5.08 | AX32: =AM32*101.97 -> 346.698 | AY32: -0.01 | AZ32: 0 | BA32: 0.6D+W60(-)
C33: Profundidad de hinca [m] | D33: 2.5 | K33: ='Pull out test IPE 160'!K29 -> 6.78 | L33: ='Pull out test IPE 160'!L12*'Interpolación para W8X10'!$E$5 -> 1693.7805 | T33: Profundidad de hinca [m] | U33: 2.5 | AK33: Poste General | AL33: 0 | AM33: 0 | AN33: 1e-06 | AO33: 2736.59 | AP33: =ABS(AO33/AN33) -> 2.73659e+09 | AQ33: 2.37 | AR33: =AQ33*101.97 -> 241.6689 | AS33: -2413 | AT33: =IF(AS33/AR33>=0,AS33/AR33, "Compresión no aplica") -> Compresión no aplica | AU33: 881.1 | AV33: =IF(AU33/AR33>=0,AU33/AR33, "Tensión no aplica") -> 3.6458973 | AW33: 0 | AX33: =AM33*101.97 -> 0 | AY33: 0.02 | AZ33: 0 | BA33: D
K34: ='Pull out test IPE 160'!K30 -> 25.5 | L34: ='Pull out test IPE 160'!L13*'Interpolación para W8X10'!$E$5 -> 2168.5366 | AK34: Poste General | AL34: 0 | AM34: -0.39 | AN34: =AM34*101.97 -> -39.7683 | AO34: 2736.59 | AP34: =ABS(AO34/AN34) -> 68.813351 | AQ34: 2.63 | AR34: =AQ34*101.97 -> 268.1811 | AS34: -2413 | AT34: =IF(AS34/AR34>=0,AS34/AR34, "Compresión no aplica") -> Compresión no aplica | AU34: 881.1 | AV34: =IF(AU34/AR34>=0,AU34/AR34, "Tensión no aplica") -> 3.2854664 | AW34: 0.58 | AX34: =AM34*101.97 -> -39.7683 | AY34: 0.02 | AZ34: 0 | BA34: D+0.7E
K35: Profundidad de hinca [m] | L35: 2.5 | AK35: Poste General | AL35: 0 | AM35: -0.39 | AN35: =AM35*101.97 -> -39.7683 | AO35: 2736.59 | AP35: =ABS(AO35/AN35) -> 68.813351 | AQ35: 1.68 | AR35: =AQ35*101.97 -> 171.3096 | AS35: -2413 | AT35: =IF(AS35/AR35>=0,AS35/AR35, "Compresión no aplica") -> Compresión no aplica | AU35: 881.1 | AV35: =IF(AU35/AR35>=0,AU35/AR35, "Tensión no aplica") -> 5.1433195 | AW35: 0.58 | AX35: =AM35*101.97 -> -39.7683 | AY35: 0.01 | AZ35: 0 | BA35: 0.6D+0.7E
AK36: Poste General | AL36: 0 | AM36: -0.66 | AN36: =AM36*101.97 -> -67.3002 | AO36: 2736.59 | AP36: =ABS(AO36/AN36) -> 40.662435 | AQ36: 4.81 | AR36: =AQ36*101.97 -> 490.4757 | AS36: -2413 | AT36: =IF(AS36/AR36>=0,AS36/AR36, "Compresión no aplica") -> Compresión no aplica | AU36: 881.1 | AV36: =IF(AU36/AR36>=0,AU36/AR36, "Tensión no aplica") -> 1.7964193 | AW36: 0.99 | AX36: =AM36*101.97 -> -67.3002 | AY36: 0.03 | AZ36: 0 | BA36: D+0.75W15(+)
AK37: Poste General | AL37: 0 | AM37: 0.58 | AN37: =AM37*101.97 -> 59.1426 | AO37: 2736.59 | AP37: =ABS(AO37/AN37) -> 46.271047 | AQ37: 0.23 | AR37: =AQ37*101.97 -> 23.4531 | AS37: -2413 | AT37: =IF(AS37/AR37>=0,AS37/AR37, "Compresión no aplica") -> Compresión no aplica | AU37: 881.1 | AV37: =IF(AU37/AR37>=0,AU37/AR37, "Tensión no aplica") -> 37.568594 | AW37: -0.87 | AX37: =AM37*101.97 -> 59.1426 | AY37: 0 | AZ37: 0 | BA37: D+0.75 W15(-)
AK38: Poste General | AL38: 0 | AM38: -2.96 | AN38: =AM38*101.97 -> -301.8312 | AO38: 2736.59 | AP38: =ABS(AO38/AN38) -> 9.066624 | AQ38: 4.04 | AR38: =AQ38*101.97 -> 411.9588 | AS38: -2413 | AT38: =IF(AS38/AR38>=0,AS38/AR38, "Compresión no aplica") -> Compresión no aplica | AU38: 881.1 | AV38: =IF(AU38/AR38>=0,AU38/AR38, "Tensión no aplica") -> 2.1388061 | AW38: 4.43 | AX38: =AM38*101.97 -> -301.8312 | AY38: 0.03 | AZ38: 0 | BA38: D+0.75W60(+)
AK39: Poste General | AL39: 0 | AM39: 2.55 | AN39: =AM39*101.97 -> 260.0235 | AO39: 2736.59 | AP39: =ABS(AO39/AN39) -> 10.524395 | AQ39: 0.92 | AR39: =AQ39*101.97 -> 93.8124 | AS39: -2413 | AT39: =IF(AS39/AR39>=0,AS39/AR39, "Compresión no aplica") -> Compresión no aplica | AU39: 881.1 | AV39: =IF(AU39/AR39>=0,AU39/AR39, "Tensión no aplica") -> 9.3921486 | AW39: -3.81 | AX39: =AM39*101.97 -> 260.0235 | AY39: 0 | AZ39: 0 | BA39: D+0.75W60(-)
AK40: Poste General | AL40: 0 | AM40: -0.86 | AN40: =AM40*101.97 -> -87.6942 | AO40: 2736.59 | AP40: =ABS(AO40/AN40) -> 31.206055 | AQ40: 5.5 | AR40: =AQ40*101.97 -> 560.835 | AS40: -2413 | AT40: =IF(AS40/AR40>=0,AS40/AR40, "Compresión no aplica") -> Compresión no aplica | AU40: 881.1 | AV40: =IF(AU40/AR40>=0,AU40/AR40, "Tensión no aplica") -> 1.5710503 | AW40: 1.28 | AX40: =AM40*101.97 -> -87.6942 | AY40: -0.02 | AZ40: 0 | BA40: D+W15(+)
AK41: Poste General | AL41: 0 | AM41: 0.76 | AN41: =AM41*101.97 -> 77.4972 | AO41: 2736.59 | AP41: =ABS(AO41/AN41) -> 35.312115 | AQ41: -0.49 | AR41: =AQ41*101.97 -> -49.9653 | AS41: -2413 | AT41: =IF(AS41/AR41>=0,AS41/AR41, "Compresión no aplica") -> 48.293516 | AU41: 881.1 | AV41: =IF(AU41/AR41>=0,AU41/AR41, "Tensión no aplica") -> Tensión no aplica | AW41: -1.13 | AX41: =AM41*101.97 -> 77.4972 | AY41: 0.01 | AZ41: 0 | BA41: D+W15(-)
C42: Correlación prueba lateral 1 para W8X10 | K42: Correlación prueba lateral 2 para W8X10 | T42: Correlación prueba lateral 3 para W8X10 | AK42: Poste General | AL42: 0 | AM42: -3.82 | AN42: =AM42*101.97 -> -389.5254 | AO42: 2736.59 | AP42: =ABS(AO42/AN42) -> 7.0254469 | AQ42: 4.5 | AR42: =AQ42*101.97 -> 458.865 | AS42: -2413 | AT42: =IF(AS42/AR42>=0,AS42/AR42, "Compresión no aplica") -> Compresión no aplica | AU42: 881.1 | AV42: =IF(AU42/AR42>=0,AU42/AR42, "Tensión no aplica") -> 1.9201726 | AW42: 5.72 | AX42: =AM42*101.97 -> -389.5254 | AY42: -0.02 | AZ42: 0 | BA42: D+W60(+)
C43: Prueba de carga lateral | K43: Prueba de carga lateral | T43: Prueba de carga lateral | AK43: Poste General | AL43: 0 | AM43: 3.29 | AN43: =AM43*101.97 -> 335.4813 | AO43: 2736.59 | AP43: =ABS(AO43/AN43) -> 8.1572058 | AQ43: 0.41 | AR43: =AQ43*101.97 -> 41.8077 | AS43: -2413 | AT43: =IF(AS43/AR43>=0,AS43/AR43, "Compresión no aplica") -> Compresión no aplica | AU43: 881.1 | AV43: =IF(AU43/AR43>=0,AU43/AR43, "Tensión no aplica") -> 21.075065 | AW43: -4.93 | AX43: =AM43*101.97 -> 335.4813 | AY43: 0 | AZ43: 0 | BA43: D+W60(-)
...

Sheet Interpolación para W8X15
C2: Item | D2: H | E2: B
C3: Dimensiones IPE 160 | D3: 160 | E3: 82 | G3: Nota el ensayo fue realizado por el lado fuerte
C4: Dimensiones W8X15 (Ala expandida) | D4: 206 | E4: 170
C5: Correlación dimensional IPE 160 a W8X15 | D5: =D4/D3 -> 1.2875 | E5: =E4/E3 -> 2.0731707
AK8: FX (kN) | AL8: FY (kN) | AM8: FY (kg) | AN8: Umbral carga lateral | AO8: F.S. Carga lateral | AP8: FZ (kN) | AQ8: FZ (kg) | AR8: Carga maxima a tensión (kg) | AS8: F.S Tensión | AT8: Carga maxima a compresión (kg) | AU8: F.S Compresión | AV8: MX (kNm) | AW8: MY (kNm) | AX8: MZ (kNm) | AY8: Case name
T9: Correlación prueba vertical 3 para W8X15 | AJ9: Poste Motor | AK9: 0 | AL9: -0.71 | AM9: =AL9*101.97 -> -72.3987 | AN9: 2736.59 | AO9: =ABS(AN9/AM9) -> 37.798883 | AP9: 5.72 | AQ9: =AP9*101.97 -> 583.2684 | AR9: 2905 | AS9: =IF(AR9/AP9>=0,AR9/AP9, "Compresión no aplica") -> 507.86713 | AT9: 875 | AU9: =IF(AT9/AQ9>=0,AT9/AQ9, "Tensión no aplica") -> 1.500167 | AV9: 9.99 | AW9: 0 | AX9: 0 | AY9: D+W15(+)
C10: Correlación prueba vertical 1 para W8X15 | K10: Correlación prueba vertical 2 para W8X15 | T10: Prueba de tensión vertical | AJ10: Poste Motor | AK10: 0 | AL10: 0.58 | AM10: =AL10*101.97 -> 59.1426 | AN10: 2736.59 | AO10: =ABS(AN10/AM10) -> 46.271047 | AP10: 0.02 | AQ10: =AP10*101.97 -> 2.0394 | AR10: 2905 | AS10: =IF(AR10/AP10>=0,AR10/AP10, "Compresión no aplica") -> 145250 | AT10: 875 | AU10: =IF(AT10/AQ10>=0,AT10/AQ10, "Tensión no aplica") -> 429.04776 | AV10: -11.94 | AW10: 0 | AX10: 0 | AY10: D+W15(-)
C11: Prueba de tensión vertical | K11: Prueba de tensión vertical | T11: Desplazamiento [mm] | U11: Fuerza [kg] | AJ11: Poste Motor | AK11: 0 | AL11: -3.58 | AM11: =AL11*101.97 -> -365.0526 | AN11: 2736.59 | AO11: =ABS(AN11/AM11) -> 7.4964265 | AP11: 4.77 | AQ11: =AP11*101.97 -> 486.3969 | AR11: 2905 | AS11: =IF(AR11/AP11>=0,AR11/AP11, "Compresión no aplica") -> 609.01468 | AT11: 875 | AU11: =IF(AT11/AQ11>=0,AT11/AQ11, "Tensión no aplica") -> 1.7989424 | AV11: 13.28 | AW11: 0 | AX11: 0 | AY11: D+W60(+)
C12: Desplazamiento [mm] | D12: Fuerza [kg] | K12: Desplazamiento [mm] | L12: Fuerza [kg] | T12: ='Pull out test IPE 160'!T8/'Interpolación para W8X15'!$D$5 -> 0 | U12: ='Pull out test IPE 160'!U8*'Interpolación para W8X15'!$E$5 -> 0 | AJ12: Poste Motor | AK12: 0 | AL12: 3.03 | AM12: =AL12*101.97 -> 308.9691 | AN12: 2736.59 | AO12: =ABS(AN12/AM12) -> 8.857164 | AP12: 0.88 | AQ12: =AP12*101.97 -> 89.7336 | AR12: 2905 | AS12: =IF(AR12/AP12>=0,AR12/AP12, "Compresión no aplica") -> 3301.1364 | AT12: 875 | AU12: =IF(AT12/AQ12>=0,AT12/AQ12, "Tensión no aplica") -> 9.7510854 | AV12: -15.63 | AW12: 0 | AX12: 0 | AY12: D+W60(-)
C13: ='Pull out test IPE 160'!C9/'Interpolación para W8X15'!$D$5 -> 0 | D13: ='Pull out test IPE 160'!D9/E5 -> 0 | K13: ='Pull out test IPE 160'!K9/'Interpolación para W8X15'!$D$5 -> 0 | L13: ='Pull out test IPE 160'!L9*'Interpolación para W8X15'!$E$5 -> 0 | T13: ='Pull out test IPE 160'!T9/'Interpolación para W8X15'!$D$5 -> 0.15533981 | U13: ='Pull out test IPE 160'!U9*'Interpolación para W8X15'!$E$5 -> 733.90244 | AJ13: Poste Motor | AK13: 0 | AL13: -0.71 | AM13: =AL13*101.97 -> -72.3987 | AN13: 2736.59 | AO13: =ABS(AN13/AM13) -> 37.798883 | AP13: 4.64 | AQ13: =AP13*101.97 -> 473.1408 | AR13: 2905 | AS13: =IF(AR13/AP13>=0,AR13/AP13, "Compresión no aplica") -> 626.07759 | AT13: 875 | AU13: =IF(AT13/AQ13>=0,AT13/AQ13, "Tensión no aplica") -> 1.8493438 | AV13: 9.99 | AW13: 0 | AX13: 0 | AY13: 0.6D+W15(+)
C14: ='Pull out test IPE 160'!C10/'Interpolación para W8X15'!$D$5 -> 0.19417476 | D14: ='Pull out test IPE 160'!D10 -> 326 | K14: ='Pull out test IPE 160'!K10/'Interpolación para W8X15'!$D$5 -> 0.069902913 | L14: ='Pull out test IPE 160'!L10*'Interpolación para W8X15'!$E$5 -> 833.41463 | T14: ='Pull out test IPE 160'!T10/'Interpolación para W8X15'!$D$5 -> 0.69902913 | U14: ='Pull out test IPE 160'!U10*'Interpolación para W8X15'!$E$5 -> 1202.439 | AJ14: Poste Motor | AK14: 0 | AL14: 0.58 | AM14: =AL14*101.97 -> 59.1426 | AN14: 2736.59 | AO14: =ABS(AN14/AM14) -> 46.271047 | AP14: -1.05 | AQ14: =AP14*101.97 -> -107.0685 | AR14: 2905 | AS14: =IF(AR14/AP14>=0,AR14/AP14, "Compresión no aplica") -> Compresión no aplica | AT14: 875 | AU14: =IF(AT14/AQ14>=0,AT14/AQ14, "Tensión no aplica") -> Tensión no aplica | AV14: -11.94 | AW14: 0 | AX14: 0 | AY14: 0.6D+W15(-)
C15: ='Pull out test IPE 160'!C11/'Interpolación para W8X15'!$D$5 -> 1.8640777 | D15: ='Pull out test IPE 160'!D11 -> 618 | K15: ='Pull out test IPE 160'!K11/'Interpolación para W8X15'!$D$5 -> 0.17864078 | L15: ='Pull out test IPE 160'!L11*'Interpolación para W8X15'!$E$5 -> 1281.2195 | T15: ='Pull out test IPE 160'!T11/'Interpolación para W8X15'!$D$5 -> 1.2427184 | U15: ='Pull out test IPE 160'!U11*'Interpolación para W8X15'!$E$5 -> 1577.6829 | AJ15: Poste Motor | AK15: 0 | AL15: -3.58 | AM15: =AL15*101.97 -> -365.0526 | AN15: 2736.59 | AO15: =ABS(AN15/AM15) -> 7.4964265 | AP15: 3.69 | AQ15: =AP15*101.97 -> 376.2693 | AR15: 2905 | AS15: =IF(AR15/AP15>=0,AR15/AP15, "Compresión no aplica") -> 787.26287 | AT15: 875 | AU15: =IF(AT15/AQ15>=0,AT15/AQ15, "Tensión no aplica") -> 2.3254621 | AV15: 13.28 | AW15: 0 | AX15: 0 | AY15: 0.6D+W60(+)
C16: ='Pull out test IPE 160'!C12/'Interpolación para W8X15'!$D$5 -> 3.6815534 | D16: ='Pull out test IPE 160'!D12 -> 861 | K16: ='Pull out test IPE 160'!K12/'Interpolación para W8X15'!$D$5 -> 0.55145631 | L16: ='Pull out test IPE 160'!L12*'Interpolación para W8X15'!$E$5 -> 1693.7805 | T16: ='Pull out test IPE 160'!T12/'Interpolación para W8X15'!$D$5 -> 6.0038835 | U16: ='Pull out test IPE 160'!U12*'Interpolación para W8X15'!$E$5 -> 2363.4146 | AJ16: Poste Motor | AK16: 0 | AL16: 3.03 | AM16: =AL16*101.97 -> 308.9691 | AN16: 2736.59 | AO16: =ABS(AN16/AM16) -> 8.857164 | AP16: -0.2 | AQ16: =AP16*101.97 -> -20.394 | AR16: 2905 | AS16: =IF(AR16/AP16>=0,AR16/AP16, "Compresión no aplica") -> Compresión no aplica | AT16: 875 | AU16: =IF(AT16/AQ16>=0,AT16/AQ16, "Tensión no aplica") -> Tensión no aplica | AV16: -15.63 | AW16: 0 | AX16: 0 | AY16: 0.6D+W60(-)
C17: ='Pull out test IPE 160'!C13/'Interpolación para W8X15'!$D$5 -> 9.3902913 | D17: ='Pull out test IPE 160'!D13 -> 1032 | K17: ='Pull out test IPE 160'!K13/'Interpolación para W8X15'!$D$5 -> 0.86213592 | L17: ='Pull out test IPE 160'!L13*'Interpolación para W8X15'!$E$5 -> 2168.5366 | T17: ='Pull out test IPE 160'!T13/'Interpolación para W8X15'!$D$5 -> 14.656311 | U17: ='Pull out test IPE 160'!U13*'Interpolación para W8X15'!$E$5 -> 2848.5366 | AJ17: Poste Motor | AK17: 0 | AL17: 0.0001 | AM17: =AL17*101.97 -> 0.010197 | AN17: 2736.59 | AO17: =ABS(AN17/AM17) -> 268372.07 | AP17: 2.69 | AQ17: =AP17*101.97 -> 274.2993 | AR17: 2905 | AS17: =IF(AR17/AP17>=0,AR17/AP17, "Compresión no aplica") -> 1079.9257 | AT17: 875 | AU17: =IF(AT17/AQ17>=0,AT17/AQ17, "Tensión no aplica") -> 3.1899462 | AV17: 0 | AW17: 0 | AX17: 0 | AY17: D
C18: ='Pull out test IPE 160'!C14/'Interpolación para W8X15'!$D$5 -> 19.875728 | D18: ='Pull out test IPE 160'!D14 -> 1164 | K18: ='Pull out test IPE 160'!K14/'Interpolación para W8X15'!$D$5 -> 1.6776699 | L18: ='Pull out test IPE 160'!L14*'Interpolación para W8X15'!$E$5 -> 2699.2683 | T18: ='Pull out test IPE 160'!T14/'Interpolación para W8X15'!$D$5 -> 19.798058 | U18: ='Pull out test IPE 160'!U14*'Interpolación para W8X15'!$E$5 -> 2906.5854 | AJ18: Poste Motor | AK18: 0 | AL18: -0.36 | AM18: =AL18*101.97 -> -36.7092 | AN18: 2736.59 | AO18: =ABS(AN18/AM18) -> 74.547797 | AP18: 2.93 | AQ18: =AP18*101.97 -> 298.7721 | AR18: 2905 | AS18: =IF(AR18/AP18>=0,AR18/AP18, "Compresión no aplica") -> 991.46758 | AT18: 875 | AU18: =IF(AT18/AQ18>=0,AT18/AQ18, "Tensión no aplica") -> 2.9286536 | AV18: 0.55 | AW18: 0 | AX18: 0 | AY18: D+0.7E
C19: Profundidad de hinca [m] | D19: 2.5 | K19: ='Pull out test IPE 160'!K15/'Interpolación para W8X15'!$D$5 -> 2.7262136 | L19: ='Pull out test IPE 160'!L15*'Interpolación para W8X15'!$E$5 -> 3006.0976 | T19: Profundidad de hinca [m] | U19: 2.5 | AJ19: Poste Motor | AK19: 0 | AL19: -0.36 | AM19: =AL19*101.97 -> -36.7092 | AN19: 2736.59 | AO19: =ABS(AN19/AM19) -> 74.547797 | AP19: 1.85 | AQ19: =AP19*101.97 -> 188.6445 | AR19: 2905 | AS19: =IF(AR19/AP19>=0,AR19/AP19, "Compresión no aplica") -> 1570.2703 | AT19: 875 | AU19: =IF(AT19/AQ19>=0,AT19/AQ19, "Tensión no aplica") -> 4.6383542 | AV19: 0.55 | AW19: 0 | AX19: 0 | AY19: 0.6D+0.7E
K20: ='Pull out test IPE 160'!K16/'Interpolación para W8X15'!$D$5 -> 5.0718447 | L20: ='Pull out test IPE 160'!L16*'Interpolación para W8X15'!$E$5 -> 3424.878 | AJ20: Poste Motor | AK20: 0 | AL20: -0.53 | AM20: =AL20*101.97 -> -54.0441 | AN20: 2736.59 | AO20: =ABS(AN20/AM20) -> 50.63624 | AP20: 4.96 | AQ20: =AP20*101.97 -> 505.7712 | AR20: 2905 | AS20: =IF(AR20/AP20>=0,AR20/AP20, "Compresión no aplica") -> 585.68548 | AT20: 875 | AU20: =IF(AT20/AQ20>=0,AT20/AQ20, "Tensión no aplica") -> 1.7300313 | AV20: 7.49 | AW20: 0 | AX20: 0 | AY20: D+0.75W15(+)
K21: ='Pull out test IPE 160'!K17/'Interpolación para W8X15'!$D$5 -> 11.487379 | L21: ='Pull out test IPE 160'!L17*'Interpolación para W8X15'!$E$5 -> 3860.2439 | AJ21: Poste Motor | AK21: 0 | AL21: 0.43 | AM21: =AL21*101.97 -> 43.8471 | AN21: 2736.59 | AO21: =ABS(AN21/AM21) -> 62.412109 | AP21: 0.69 | AQ21: =AP21*101.97 -> 70.3593 | AR21: 2905 | AS21: =IF(AR21/AP21>=0,AR21/AP21, "Compresión no aplica") -> 4210.1449 | AT21: 875 | AU21: =IF(AT21/AQ21>=0,AT21/AQ21, "Tensión no aplica") -> 12.436167 | AV21: -8.96 | AW21: 0 | AX21: 0 | AY21: D+0.75 W15(-)
K22: ='Pull out test IPE 160'!K18/'Interpolación para W8X15'!$D$5 -> 19.92233 | L22: ='Pull out test IPE 160'!L18*'Interpolación para W8X15'!$E$5 -> 4005.3659 | AJ22: Poste Motor | AK22: 0 | AL22: -2.69 | AM22: =AL22*101.97 -> -274.2993 | AN22: 2736.59 | AO22: =ABS(AN22/AM22) -> 9.9766569 | AP22: 4.25 | AQ22: =AP22*101.97 -> 433.3725 | AR22: 2905 | AS22: =IF(AR22/AP22>=0,AR22/AP22, "Compresión no aplica") -> 683.52941 | AT22: 875 | AU22: =IF(AT22/AQ22>=0,AT22/AQ22, "Tensión no aplica") -> 2.0190483 | AV22: 9.96 | AW22: 0 | AX22: 0 | AY22: D+0.75W60(+)
K23: Profundidad de hinca [m] | L23: 2.5 | AJ23: Poste Motor | AK23: 0 | AL23: 2.27 | AM23: =AL23*101.97 -> 231.4719 | AN23: 2736.59 | AO23: =ABS(AN23/AM23) -> 11.822558 | AP23: 1.33 | AQ23: =AP23*101.97 -> 135.6201 | AR23: 2905 | AS23: =IF(AR23/AP23>=0,AR23/AP23, "Compresión no aplica") -> 2184.2105 | AT23: 875 | AU23: =IF(AT23/AQ23>=0,AT23/AQ23, "Tensión no aplica") -> 6.451846 | AV23: -11.72 | AW23: 0 | AX23: 0 | AY23: D+0.75W60(-)
C27: Correlación prueba vertical 1 para W8X15 | K27: Correlación prueba vertical 2 para W8X15 | T27: Correlación prueba vertical 3 para W8X15
C28: Prueba de compresión vertical | K28: Prueba de compresión vertical | T28: Prueba de compresión vertical
C29: Desplazamiento [mm] | D29: Fuerza [kg] | K29: Desplazamiento [mm] | L29: Fuerza [kg] | T29: Desplazamiento [mm] | U29: Fuerza [kg]
C30: ='Pull out test IPE 160'!C26/'Interpolación para W8X15'!$D$5 -> 0 | D30: ='Pull out test IPE 160'!D26*'Interpolación para W8X15'!$E$5 -> 0 | K30: ='Pull out test IPE 160'!K26/'Interpolación para W8X15'!$D$5 -> 0 | L30: ='Pull out test IPE 160'!L26*'Interpolación para W8X15'!$E$5 -> 0 | T30: ='Pull out test IPE 160'!T26/$D$5 -> 0 | U30: ='Pull out test IPE 160'!U26*'Interpolación para W8X15'!$E$5 -> 0
C31: ='Pull out test IPE 160'!C27/'Interpolación para W8X15'!$D$5 -> 9.4601942 | D31: ='Pull out test IPE 160'!D27*'Interpolación para W8X15'!$E$5 -> 709.02439 | K31: ='Pull out test IPE 160'!K27/'Interpolación para W8X15'!$D$5 -> 0.83106796 | L31: ='Pull out test IPE 160'!L27*'Interpolación para W8X15'!$E$5 -> 723.53659 | T31: ='Pull out test IPE 160'!T27/$D$5 -> 8.1242718 | U31: ='Pull out test IPE 160'!U27*'Interpolación para W8X15'!$E$5 -> 688.29268
C32: ='Pull out test IPE 160'!C28/'Interpolación para W8X15'!$D$5 -> 20.038835 | D32: ='Pull out test IPE 160'!D28*'Interpolación para W8X15'!$E$5 -> 881.09756 | K32: ='Pull out test IPE 160'!K28/'Interpolación para W8X15'!$D$5 -> 2.4543689 | L32: ='Pull out test IPE 160'!L28*'Interpolación para W8X15'!$E$5 -> 1078.0488 | T32: ='Pull out test IPE 160'!T28/$D$5 -> 20.038835 | U32: ='Pull out test IPE 160'!U28*'Interpolación para W8X15'!$E$5 -> 870.73171
C33: Profundidad de hinca [m] | D33: 2.5 | K33: ='Pull out test IPE 160'!K29/'Interpolación para W8X15'!$D$5 -> 5.2660194 | L33: ='Pull out test IPE 160'!L29*'Interpolación para W8X15'!$E$5 -> 1619.1463 | T33: Profundidad de hinca [m] | U33: 2.5
K34: ='Pull out test IPE 160'!K30/'Interpolación para W8X15'!$D$5 -> 19.805825 | L34: ='Pull out test IPE 160'!L30*'Interpolación para W8X15'!$E$5 -> 2040
K35: Profundidad de hinca [m] | L35: 2.5
C42: Correlación prueba lateral 1 para W8X15 | K42: Correlación prueba lateral 2 para W8X15 | T42: Correlación prueba lateral 3 para W8X15
C43: Prueba de carga lateral | K43: Prueba de carga lateral | T43: Prueba de carga lateral
C44: Desplazamiento [mm] | D44: Fuerza [kg] | K44: Desplazamiento [mm] | L44: Fuerza [kg] | T44: Desplazamiento [mm] | U44: Fuerza [kg]
C45: ='Pull out test IPE 160'!C41/'Interpolación para W8X15'!$D$5 -> 0 | D45: ='Pull out test IPE 160'!D41*'Interpolación para W8X15'!$E$5 -> 0 | K45: ='Pull out test IPE 160'!K41/'Interpolación para W8X15'!$D$5 -> 0 | L45: ='Pull out test IPE 160'!L41*'Interpolación para W8X15'!$E$5 -> 0 | T45: 0 | U45: ='Pull out test IPE 160'!U41*'Interpolación para W8X15'!$E$5 -> 0
C46: ='Pull out test IPE 160'!C42/'Interpolación para W8X15'!$D$5 -> 3.4485437 | D46: ='Pull out test IPE 160'!D42*'Interpolación para W8X15'!$E$5 -> 725.60976 | K46: ='Pull out test IPE 160'!K42/'Interpolación para W8X15'!$D$5 -> 1.7087379 | L46: ='Pull out test IPE 160'!L42*'Interpolación para W8X15'!$E$5 -> 642.68293 | T46: ='Pull out test IPE 160'!T42/'Interpolación para W8X15'!$D$5 -> 2.392233 | U46: ='Pull out test IPE 160'!U42*'Interpolación para W8X15'!$E$5 -> 663.41463
C47: ='Pull out test IPE 160'!C43/'Interpolación para W8X15'!$D$5 -> 5.1572816 | D47: ='Pull out test IPE 160'!D43*'Interpolación para W8X15'!$E$5 -> 1086.3415 | K47: ='Pull out test IPE 160'!K43/'Interpolación para W8X15'!$D$5 -> 2.423301 | L47: ='Pull out test IPE 160'!L43*'Interpolación para W8X15'!$E$5 -> 1140.2439 | T47: ='Pull out test IPE 160'!T43/'Interpolación para W8X15'!$D$5 -> 3.3242718 | U47: ='Pull out test IPE 160'!U43*'Interpolación para W8X15'!$E$5 -> 1098.7805
C48: ='Pull out test IPE 160'!C44/'Interpolación para W8X15'!$D$5 -> 7.8524272 | D48: ='Pull out test IPE 160'!D44*'Interpolación para W8X15'!$E$5 -> 1488.5366 | K48: ='Pull out test IPE 160'!K44/'Interpolación para W8X15'!$D$5 -> 3.4407767 | L48: ='Pull out test IPE 160'!L44*'Interpolación para W8X15'!$E$5 -> 1509.2683 | T48: ='Pull out test IPE 160'!T44/'Interpolación para W8X15'!$D$5 -> 5.1572816 | U48: ='Pull out test IPE 160'!U44*'Interpolación para W8X15'!$E$5 -> 1538.2927
C49: ='Pull out test IPE 160'!C45/'Interpolación para W8X15'!$D$5 -> 13.405825 | D49: ='Pull out test IPE 160'!D45*'Interpolación para W8X15'!$E$5 -> 2135.3659 | K49: ='Pull out test IPE 160'!K45/'Interpolación para W8X15'!$D$5 -> 5.3514563 | L49: ='Pull out test IPE 160'!L45*'Interpolación para W8X15'!$E$5 -> 2156.0976 | T49: ='Pull out test IPE 160'!T45/'Interpolación para W8X15'!$D$5 -> 8.0776699 | U49: ='Pull out test IPE 160'!U45*'Interpolación para W8X15'!$E$5 -> 2147.8049
C50: ='Pull out test IPE 160'!C46/'Interpolación para W8X15'!$D$5 -> 19.106796 | D50: ='Pull out test IPE 160'!D46*'Interpolación para W8X15'!$E$5 -> 2570.7317 | K50: ='Pull out test IPE 160'!K46/'Interpolación para W8X15'!$D$5 -> 7.4407767 | L50: ='Pull out test IPE 160'!L46*'Interpolación para W8X15'!$E$5 -> 2628.7805 | T50: ='Pull out test IPE 160'!T46/'Interpolación para W8X15'!$D$5 -> 10.96699 | U50: ='Pull out test IPE 160'!U46*'Interpolación para W8X15'!$E$5 -> 2653.6585
C51: ='Pull out test IPE 160'!C47/'Interpolación para W8X15'!$D$5 -> 19.860194 | D51: ='Pull out test IPE 160'!D47*'Interpolación para W8X15'!$E$5 -> 2736.5854 | K51: ='Pull out test IPE 160'!K47/'Interpolación para W8X15'!$D$5 -> 8.9631068 | L51: ='Pull out test IPE 160'!L47*'Interpolación para W8X15'!$E$5 -> 3030.9756 | T51: ='Pull out test IPE 160'!T47/'Interpolación para W8X15'!$D$5 -> 13.126214 | U51: ='Pull out test IPE 160'!U47*'Interpolación para W8X15'!$E$5 -> 3037.1951
C52: Profundidad de hinca [m] | D52: 2.5 | K52: ='Pull out test IPE 160'!K48/'Interpolación para W8X15'!$D$5 -> 10.796117 | L52: ='Pull out test IPE 160'!L48*'Interpolación para W8X15'!$E$5 -> 3429.0244 | T52: ='Pull out test IPE 160'!T48/'Interpolación para W8X15'!$D$5 -> 15.92233 | U52: ='Pull out test IPE 160'!U48*'Interpolación para W8X15'!$E$5 -> 3387.561
...

Sheet Hoja2
